Workbook
Name SAT_WATCH: Satellite_Watchlist!$B$1:$D$998

Sheet Dashboard
A1: 📊 Portfolio Dashboard | I1: 🕒 Last Transacted Date: 02 Jun 2026
A3: Portfolio Summary | D3: Trading Performance | I3: 📈 Benchmark Returns (Since Invest Start)
A4: Metric | B4: Value | D4: Metric | E4: Realized (Closed) | F4: Unrealized (Open) | I4: Index Tracker (ETF) | J4: Start Price (₹) | K4: LTP (₹) | L4: Return %
A5: Total Invested Value | B5: =SUM(Current_Portfolio!$L$2:$L$1000) -> 4797975.8 | D5: Winning Trades | E5: =COUNTIF(Overall_Portfolio!$P$2:$P$1000, ">0") -> 6 | F5: =COUNTIF(Current_Portfolio!$U$2:$U$1000, ">0") -> 35 | I5: NIFTY_50 | J5: 24625.05 | K5: =IFERROR(INDEX(Price_Update!$F:$F, MATCH(I5, Price_Update!$A:$A, 0)), 23483.55) -> 23483.55 | L5: =(K5-J5)/J5 -> -0.046355236
A6: Total Current Value | B6: =SUM(Current_Portfolio!$T$2:$T$1000) -> 5334209.9 | D6: Losing Trades | E6: =COUNTIF(Overall_Portfolio!$P$2:$P$1000, "<0") -> 41 | F6: =COUNTIF(Current_Portfolio!$U$2:$U$1000, "<0") -> 25 | I6: CNXMIDCAP | J6: 16033.55 | K6: =IFERROR(INDEX(Price_Update!$F:$F, MATCH(I6, Price_Update!$A:$A, 0)), 17287.3) -> 17287.3 | L6: =(K6-J6)/J6 -> 0.078195409
A7: Unrealized PnL | B7: =B6-B5 -> 536234.1 | D7: Win / Loss Ratio | E7: =IF(E6>0, E5/E6, IF(E5>0, "No Loss", 0)) -> 0.14634146 | F7: =IF(F6>0, F5/F6, IF(F5>0, "No Loss", 0)) -> 1.4
A8: Realized PnL | B8: =SUM(Overall_Portfolio!$P$2:$P$1000) -> -426233.83 | D8: Avg Win (₹) | E8: =IF(E5>0, SUMIF(Overall_Portfolio!$P$2:$P$1000, ">0")/E5, 0) -> 2800.56 | F8: =IF(F5>0, SUMIF(Current_Portfolio!$U$2:$U$1000, ">0")/F5, 0) -> 16967.158
A9: Combined PnL | B9: =B7+B8 -> 110000.27 | D9: Avg Loss (₹) | E9: =IF(E6>0, SUMIF(Overall_Portfolio!$P$2:$P$1000, "<0")/E6, 0) -> -10805.785 | F9: =IF(F6>0, SUMIF(Current_Portfolio!$U$2:$U$1000, "<0")/F6, 0) -> -2304.6576 | I9: Allocation by Market Cap
A10: Combined PnL % | B10: =IF(B5>0, B9/B5, 0) -> 0.022926391 | D10: Risk / Reward Ratio | E10: =IF(E9<0, ABS(E8/E9), 0) -> 0.25917228 | F10: =IF(F9<0, ABS(F8/F9), 0) -> 7.3621167 | I10: Market Cap | J10: Invested (₹) | K10: % of Total | L10: Returns
A11: Core Allocation (%) | B11: =IF(B5>0, SUMIF(Current_Portfolio!$D$2:$D$1000, "Core", Current_Portfolio!$L$2:$L$1000) / B5, 0) -> 0.57352989 | I11: Small Cap | J11: =SUMIF(Current_Portfolio!$B$2:$B$1000, "Small Cap", Current_Portfolio!$L$2:$L$1000) -> 2126996.7 | K11: =J11/$J$14 -> 0.44331127 | L11: =(SUMIF(Current_Portfolio!$B$2:$B$1000, "Small Cap", Current_Portfolio!$T$2:$T$1000) - J11) / J11 -> 0.11581849
A12: Satellite Allocation (%) | B12: =IF(B5>0, SUMIF(Current_Portfolio!$D$2:$D$1000, "Satellite", Current_Portfolio!$L$2:$L$1000) / B5, 0) -> 0.42647011 | E12: Advancing | F12: Declining | I12: Large Cap | J12: =SUMIF(Current_Portfolio!$B$2:$B$1000, "Large Cap", Current_Portfolio!$L$2:$L$1000) -> 1722033.7 | K12: =J12/$J$14 -> 0.35890838 | L12: =(SUMIF(Current_Portfolio!$B$2:$B$1000, "Large Cap", Current_Portfolio!$T$2:$T$1000) - J12) / J12 -> 0.15475051
A13: Active Holdings | B13: =COUNTA(Current_Portfolio!$A$2:$A$1000) -> 60 | D13: Core (Previous month close) | E13: =SUMPRODUCT((Current_Portfolio!$D$2:$D$1000="Core")*(Current_Portfolio!$M$2:$M$1000>Current_Portfolio!$AA$2:$AA$1000)*(Current_Portfolio!$M$2:$M$1000>0)) -> 15 | F13: =SUMPRODUCT((Current_Portfolio!$D$2:$D$1000="Core")*(Current_Portfolio!$M$2:$M$1000<=Current_Portfolio!$AA$2:$AA$1000)*(Current_Portfolio!$M$2:$M$1000>0)) -> 23 | I13: Mid Cap | J13: =SUMIF(Current_Portfolio!$B$2:$B$1000, "Mid Cap", Current_Portfolio!$L$2:$L$1000) -> 948945.36 | K13: =J13/$J$14 -> 0.19778036 | L13: =(SUMIF(Current_Portfolio!$B$2:$B$1000, "Mid Cap", Current_Portfolio!$T$2:$T$1000) - J13) / J13 -> 0.024662052
A14: Total Stocks Traded | B14: =COUNTA(Overall_Portfolio!$A$2:$A$1000) -> 100 | D14: Satellite (Previous week close) | E14: =SUMPRODUCT((Current_Portfolio!$D$2:$D$1000="Satellite")*(Current_Portfolio!$M$2:$M$1000>Current_Portfolio!$O$2:$O$1000)*(Current_Portfolio!$M$2:$M$1000>0)) -> 11 | F14: =SUMPRODUCT((Current_Portfolio!$D$2:$D$1000="Satellite")*(Current_Portfolio!$M$2:$M$1000<=Current_Portfolio!$O$2:$O$1000)*(Current_Portfolio!$M$2:$M$1000>0)) -> 11 | I14: TOTAL | J14: =SUM(J11:J13) -> 4797975.8 | K14: 1 | L14: =(SUM(Current_Portfolio!$T$2:$T$1000) - J14) / J14 -> 0.11176257
D15: Core (Previous Close) | E15: =SUMPRODUCT((Current_Portfolio!$D$2:$D$1000="Core")*(Current_Portfolio!$M$2:$M$1000>Current_Portfolio!$N$2:$N$1000)*(Current_Portfolio!$M$2:$M$1000>0)) -> 19 | F15: =SUMPRODUCT((Current_Portfolio!$D$2:$D$1000="Core")*(Current_Portfolio!$M$2:$M$1000<=Current_Portfolio!$N$2:$N$1000)*(Current_Portfolio!$M$2:$M$1000>0)) -> 19
D16: Satellite (Previous Close) | E16: =SUMPRODUCT((Current_Portfolio!$D$2:$D$1000="Satellite")*(Current_Portfolio!$M$2:$M$1000>Current_Portfolio!$N$2:$N$1000)*(Current_Portfolio!$M$2:$M$1000>0)) -> 6 | F16: =SUMPRODUCT((Current_Portfolio!$D$2:$D$1000="Satellite")*(Current_Portfolio!$M$2:$M$1000<=Current_Portfolio!$N$2:$N$1000)*(Current_Portfolio!$M$2:$M$1000>0)) -> 16
A17: Top 5 Gainers / Bottom 5 Losers (Satellite) | I17: Core & Satellite Distribution
A18: Symbol | B18: Classification | C18: Invested (₹) | D18: Current (₹) | E18: PnL (₹) | F18: PnL % | I18: Classification | J18: Invested (₹) | K18: % of Total
A19: HINDALCO | B19: Satellite | C19: =VLOOKUP(A19, Current_Portfolio!$A$2:$Z$1000, 12, FALSE) -> 306836.4 | D19: =VLOOKUP(A19, Current_Portfolio!$A$2:$Z$1000, 20, FALSE) -> 387226 | E19: =D19-C19 -> 80389.6 | F19: =IF(C19>0, E19/C19, 0) -> 0.26199499 | I19: Core | J19: =SUMIF(Current_Portfolio!$D$2:$D$1000, "Core", Current_Portfolio!$L$2:$L$1000) -> 2751782.5 | K19: =J19/$J$21 -> 0.57352989
A20: CUPID | B20: Satellite | C20: =VLOOKUP(A20, Current_Portfolio!$A$2:$Z$1000, 12, FALSE) -> 178375.5 | D20: =VLOOKUP(A20, Current_Portfolio!$A$2:$Z$1000, 20, FALSE) -> 236885 | E20: =D20-C20 -> 58509.5 | F20: =IF(C20>0, E20/C20, 0) -> 0.3280131 | I20: Satellite | J20: =SUMIF(Current_Portfolio!$D$2:$D$1000, "Satellite", Current_Portfolio!$L$2:$L$1000) -> 2046193.2 | K20: =J20/$J$21 -> 0.42647011
A21: APOLLO | B21: Satellite | C21: =VLOOKUP(A21, Current_Portfolio!$A$2:$Z$1000, 12, FALSE) -> 200387.96 | D21: =VLOOKUP(A21, Current_Portfolio!$A$2:$Z$1000, 20, FALSE) -> 226597.8 | E21: =D21-C21 -> 26209.84 | F21: =IF(C21>0, E21/C21, 0) -> 0.13079548 | I21: TOTAL | J21: =SUM(J19:J20) -> 4797975.8 | K21: 1
A22: BALAMINES | B22: Satellite | C22: =VLOOKUP(A22, Current_Portfolio!$A$2:$Z$1000, 12, FALSE) -> 98687.68 | D22: =VLOOKUP(A22, Current_Portfolio!$A$2:$Z$1000, 20, FALSE) -> 118843.2 | E22: =D22-C22 -> 20155.52 | F22: =IF(C22>0, E22/C22, 0) -> 0.20423542
A23: SEAMECLTD | B23: Satellite | C23: =VLOOKUP(A23, Current_Portfolio!$A$2:$Z$1000, 12, FALSE) -> 56862.54 | D23: =VLOOKUP(A23, Current_Portfolio!$A$2:$Z$1000, 20, FALSE) -> 67926.6 | E23: =D23-C23 -> 11064.06 | F23: =IF(C23>0, E23/C23, 0) -> 0.19457555
A24: THERMAX | B24: Satellite | C24: =VLOOKUP(A24, Current_Portfolio!$A$2:$Z$1000, 12, FALSE) -> 54590.58 | D24: =VLOOKUP(A24, Current_Portfolio!$A$2:$Z$1000, 20, FALSE) -> 52629.5 | E24: =D24-C24 -> -1961.08 | F24: =IF(C24>0, E24/C24, 0) -> -0.035923414 | I24: Allocation by Sector
A25: AUROPHARMA | B25: Satellite | C25: =VLOOKUP(A25, Current_Portfolio!$A$2:$Z$1000, 12, FALSE) -> 49684.8 | D25: =VLOOKUP(A25, Current_Portfolio!$A$2:$Z$1000, 20, FALSE) -> 47533.2 | E25: =D25-C25 -> -2151.6 | F25: =IF(C25>0, E25/C25, 0) -> -0.043304995 | I25: Sector | J25: Invested (₹) | K25: % of Total
A26: NRBBEARING | B26: Satellite | C26: =VLOOKUP(A26, Current_Portfolio!$A$2:$Z$1000, 12, FALSE) -> 50270.01 | D26: =VLOOKUP(A26, Current_Portfolio!$A$2:$Z$1000, 20, FALSE) -> 47527.55 | E26: =D26-C26 -> -2742.46 | F26: =IF(C26>0, E26/C26, 0) -> -0.054554594 | I26: Industrial | J26: =SUMIF(Current_Portfolio!$C$2:$C$1000, "Industrial", Current_Portfolio!$L$2:$L$1000) -> 2356830.7 | K26: =J26/$J$33 -> 0.49121354
A27: AJANTPHARM | B27: Satellite | C27: =VLOOKUP(A27, Current_Portfolio!$A$2:$Z$1000, 12, FALSE) -> 43885.24 | D27: =VLOOKUP(A27, Current_Portfolio!$A$2:$Z$1000, 20, FALSE) -> 41008.8 | E27: =D27-C27 -> -2876.44 | F27: =IF(C27>0, E27/C27, 0) -> -0.065544589 | I27: Health / Pharma / Chem | J27: =SUMIF(Current_Portfolio!$C$2:$C$1000, "Health / Pharma / Chem", Current_Portfolio!$L$2:$L$1000) -> 760481.96 | K27: =J27/$J$33 -> 0.15850058
A28: SUNPHARMA | B28: Satellite | C28: =VLOOKUP(A28, Current_Portfolio!$A$2:$Z$1000, 12, FALSE) -> 49379.2 | D28: =VLOOKUP(A28, Current_Portfolio!$A$2:$Z$1000, 20, FALSE) -> 46501 | E28: =D28-C28 -> -2878.2 | F28: =IF(C28>0, E28/C28, 0) -> -0.0582877 | I28: Consumption | J28: =SUMIF(Current_Portfolio!$C$2:$C$1000, "Consumption ", Current_Portfolio!$L$2:$L$1000) -> 536000.37 | K28: =J28/$J$33 -> 0.11171385
I29: Consumption | J29: =SUMIF(Current_Portfolio!$C$2:$C$1000, "Consumption", Current_Portfolio!$L$2:$L$1000) -> 533367.59 | K29: =J29/$J$33 -> 0.11116513
I30: Finance | J30: =SUMIF(Current_Portfolio!$C$2:$C$1000, "Finance", Current_Portfolio!$L$2:$L$1000) -> 401059.84 | K30: =J30/$J$33 -> 0.083589384
A31: Top 5 Gainers / Bottom 5 Losers (Core) | I31: Tech / Platform / IT | J31: =SUMIF(Current_Portfolio!$C$2:$C$1000, "Tech / Platform / IT", Current_Portfolio!$L$2:$L$1000) -> 150791.12 | K31: =J31/$J$33 -> 0.03142807
A32: Symbol | B32: Classification | C32: Invested (₹) | D32: Current (₹) | E32: PnL (₹) | F32: PnL % | I32: Technology | J32: =SUMIF(Current_Portfolio!$C$2:$C$1000, "Technology", Current_Portfolio!$L$2:$L$1000) -> 59444.25 | K32: =J32/$J$33 -> 0.012389443
A33: TDPOWERSYS | B33: Core | C33: =VLOOKUP(A33, Current_Portfolio!$A$2:$Z$1000, 12, FALSE) -> 305010.99 | D33: =VLOOKUP(A33, Current_Portfolio!$A$2:$Z$1000, 20, FALSE) -> 412902.3 | E33: =D33-C33 -> 107891.31 | F33: =IF(C33>0, E33/C33, 0) -> 0.35372925 | I33: TOTAL | J33: =SUM(J26:J32) -> 4797975.8 | K33: 1
A34: POLYCAB | B34: Core | C34: =VLOOKUP(A34, Current_Portfolio!$A$2:$Z$1000, 12, FALSE) -> 414743.02 | D34: =VLOOKUP(A34, Current_Portfolio!$A$2:$Z$1000, 20, FALSE) -> 507289.5 | E34: =D34-C34 -> 92546.48 | F34: =IF(C34>0, E34/C34, 0) -> 0.22314174
A35: FEDERALBNK | B35: Core | C35: =VLOOKUP(A35, Current_Portfolio!$A$2:$Z$1000, 12, FALSE) -> 300289.84 | D35: =VLOOKUP(A35, Current_Portfolio!$A$2:$Z$1000, 20, FALSE) -> 352830.6 | E35: =D35-C35 -> 52540.76 | F35: =IF(C35>0, E35/C35, 0) -> 0.17496683
A36: GVT&D | B36: Core | C36: =VLOOKUP(A36, Current_Portfolio!$A$2:$Z$1000, 12, FALSE) -> 228571.75 | D36: =VLOOKUP(A36, Current_Portfolio!$A$2:$Z$1000, 20, FALSE) -> 273047.5 | E36: =D36-C36 -> 44475.75 | F36: =IF(C36>0, E36/C36, 0) -> 0.19458113 | I36: Sector Allocation (Core vs Satellite)
A37: BSE | B37: Core | C37: =VLOOKUP(A37, Current_Portfolio!$A$2:$Z$1000, 12, FALSE) -> 100770 | D37: =VLOOKUP(A37, Current_Portfolio!$A$2:$Z$1000, 20, FALSE) -> 118983 | E37: =D37-C37 -> 18213 | F37: =IF(C37>0, E37/C37, 0) -> 0.18073831 | I37: Sector | J37: Core (₹) | K37: Satellite (₹) | L37: Total (₹)
A38: M&M | B38: Core | C38: =VLOOKUP(A38, Current_Portfolio!$A$2:$Z$1000, 12, FALSE) -> 50032 | D38: =VLOOKUP(A38, Current_Portfolio!$A$2:$Z$1000, 20, FALSE) -> 48177.6 | E38: =D38-C38 -> -1854.4 | F38: =IF(C38>0, E38/C38, 0) -> -0.037064279 | I38: Industrial | J38: =SUMIFS(Current_Portfolio!$L$2:$L$1000, Current_Portfolio!$C$2:$C$1000, "Industrial", Current_Portfolio!$D$2:$D$1000, "*Core*") -> 1108767.6 | K38: =SUMIFS(Current_Portfolio!$L$2:$L$1000, Current_Portfolio!$C$2:$C$1000, "Industrial", Current_Portfolio!$D$2:$D$1000, "*Satellite*") -> 1248063.1 | L38: =J38+K38 -> 2356830.7
A39: TRITURBINE | B39: Core | C39: =VLOOKUP(A39, Current_Portfolio!$A$2:$Z$1000, 12, FALSE) -> 78698.76 | D39: =VLOOKUP(A39, Current_Portfolio!$A$2:$Z$1000, 20, FALSE) -> 76248.9 | E39: =D39-C39 -> -2449.86 | F39: =IF(C39>0, E39/C39, 0) -> -0.031129588 | I39: Health / Pharma / Chem | J39: =SUMIFS(Current_Portfolio!$L$2:$L$1000, Current_Portfolio!$C$2:$C$1000, "Health / Pharma / Chem", Current_Portfolio!$D$2:$D$1000, "*Core*") -> 367313.89 | K39: =SUMIFS(Current_Portfolio!$L$2:$L$1000, Current_Portfolio!$C$2:$C$1000, "Health / Pharma / Chem", Current_Portfolio!$D$2:$D$1000, "*Satellite*") -> 393168.07 | L39: =J39+K39 -> 760481.96
A40: HBLENGINE | B40: Core | C40: =VLOOKUP(A40, Current_Portfolio!$A$2:$Z$1000, 12, FALSE) -> 32030.53 | D40: =VLOOKUP(A40, Current_Portfolio!$A$2:$Z$1000, 20, FALSE) -> 29091.25 | E40: =D40-C40 -> -2939.28 | F40: =IF(C40>0, E40/C40, 0) -> -0.091764951 | I40: Consumption | J40: =SUMIFS(Current_Portfolio!$L$2:$L$1000, Current_Portfolio!$C$2:$C$1000, "Consumption ", Current_Portfolio!$D$2:$D$1000, "*Core*") -> 536000.37 | K40: =SUMIFS(Current_Portfolio!$L$2:$L$1000, Current_Portfolio!$C$2:$C$1000, "Consumption ", Current_Portfolio!$D$2:$D$1000, "*Satellite*") -> 0 | L40: =J40+K40 -> 536000.37
A41: APLAPOLLO | B41: Core | C41: =VLOOKUP(A41, Current_Portfolio!$A$2:$Z$1000, 12, FALSE) -> 201676.8 | D41: =VLOOKUP(A41, Current_Portfolio!$A$2:$Z$1000, 20, FALSE) -> 173318.4 | E41: =D41-C41 -> -28358.4 | F41: =IF(C41>0, E41/C41, 0) -> -0.1406131 | I41: Consumption | J41: =SUMIFS(Current_Portfolio!$L$2:$L$1000, Current_Portfolio!$C$2:$C$1000, "Consumption", Current_Portfolio!$D$2:$D$1000, "*Core*") -> 279196.59 | K41: =SUMIFS(Current_Portfolio!$L$2:$L$1000, Current_Portfolio!$C$2:$C$1000, "Consumption", Current_Portfolio!$D$2:$D$1000, "*Satellite*") -> 254171 | L41: =J41+K41 -> 533367.59
...

Sheet Action Tracker
A1: Date | B1: TF_Classification | C1: Stock | D1: Sector | E1: TF Classification | F1: Latest Tranch or Cheat | G1: Action (Recommended) | H1: Reason | I1: Action Taken | J1: Remarks
A2: 29-05-2026 | B2: Satellite | C2: GPIL | D2: Industrial | E2: Satellite | F2: Cheat 2 | G2: SELL | H2: Cheat holding period long and less return (214 days, 1.56% return) | I2: No | J2: Sakthiman- OK,
A3: 29-05-2026 | B3: Satellite | C3: AJANTPHARM | D3: Health / Pharma / Chem | E3: Satellite | F3: Cheat 2 | G3: SELL | H3: Cheat holding period long and red (144 days, -4.47% return) | I3: No | J3: Sakthiman- OK,
A4: 29-05-2026 | B4: Satellite | C4: LAURUSLABS | D4: Health / Pharma / Chem | E4: Satellite | F4: Cheat 1 | G4: SELL | H4: Cheat holding period long and less return (14 days, 3.74% return) | I4: No | J4: Sakthiman- OK,
A5: 29-05-2026 | B5: Satellite | C5: AUROPHARMA | D5: Health / Pharma / Chem | E5: Satellite | F5: Cheat 1 | G5: SELL | H5: Cheat holding period long and red (11 days, -4.00% return) | I5: No | J5: Sakthiman- OK,
A6: 29-05-2026 | B6: Satellite | C6: SUNPHARMA | D6: Health / Pharma / Chem | E6: Satellite | F6: Cheat 1 | G6: SELL | H6: Cheat holding period long and red (11 days, -3.09% return) | I6: No | J6: Sakthiman- OK,
A7: 29-05-2026 | B7: Satellite | C7: POCL | D7: Industrial | E7: Satellite | F7: Tranch 1 | G7: SELL | H7: Tranch LTP close to stop loss (< 5% difference) | I7: No | J7: Sakthiman- X, Reversing Positively, Wait Mode
A8: 29-05-2026 | B8: Satellite | C8: GAEL | D8: Consumption | E8: Satellite | F8: Cheat 2 | G8: ADD | H8: Cheat positive return (147 days, 14.90% return, -2.46% return from prev week close) | I8: No | J8: Weekly Red Candle Shaktimaan shows Green and "C" even though the weekly candle is red "Green" indicates a positive trend signal "C" typically suggests consolidation or caution but not a sell signal In this case, the green color in Shaktimaan outweighs the red candle, meaning the overall trend is still positive. So, the strategy remains: 🔵 Hold your position for now.
A9: 29-05-2026 | B9: Satellite | C9: NMDC | D9: Industrial | E9: Satellite | F9: Cheat 1 | G9: ADD | H9: Cheat positive return (147 days, 8.49% return, 4.34% return from prev week close) | I9: Yes | J9: Weekly candle is higher than previous week closing Shaktimaan shows B (Green) Donchian Channel breakout two weekly candles back The strategy is: Buy/Add position
A10: 29-05-2026 | B10: Satellite | C10: SEAMECLTD | D10: Industrial | E10: Satellite | F10: Cheat 4 | G10: ADD | H10: Cheat positive return (119 days, 20.27% return, 1.28% return from prev week close) | I10: No | J10: This week red candle but current price is above last week's green candle close Has NOT formed a new weekly high compared to previous week
A11: 29-05-2026 | B11: Satellite | C11: CGPOWER | D11: Industrial | E11: Satellite | F11: Cheat 3 | G11: ADD | H11: Cheat positive return (106 days, 15.78% return, 7.10% return from prev week close) | I11: Yes | J11: Green Candle, DC High, Volume almost equivalent to Average
A12: 29-05-2026 | B12: Satellite | C12: ASTRAMICRO | D12: Industrial | E12: Satellite | F12: Cheat 1 | G12: ADD | H12: Cheat positive return (32 days, 22.88% return, 19.39% return from prev week close) | I12: Yes | J12: Green candle, DC high, Above Average Volume
... A16: 29-05-2026 | B16: Satellite | C16: BALAMINES | D16: Health / Pharma / Chem | E16: Satellite | F16: Tranch 1 | G16: ADD | H16: Tranch LTP above previous week close [0 to 5%] (0.10% above) | I16: NO | J16: Red Candle, DC high, Sakthiman C
A17: 29-05-2026 | B17: Satellite | C17: CUPID | D17: Consumption | E17: Satellite | F17: Tranch 2 | G17: ADD | H17: Tranch LTP above previous week close [> 5%] (7.82% above)
A18: 29-05-2026 | B18: Satellite | C18: HINDALCO | D18: Industrial | E18: Satellite | F18: Tranch 3 | G18: ADD | H18: Tranch LTP above previous week close [0 to 5%] (3.07% above)
A19: 29-05-2026 | B19: Satellite | C19: ADANIENSOL | E19: Satellite | F19: Watchlist | G19: BUY | H19: Buy breakout (RSI: 74.3, ADX: 33.0, Vol: +53% above average)
A20: 29-05-2026 | B20: Satellite | C20: HFCL | E20: Satellite | F20: Watchlist | G20: BUY | H20: Buy breakout (RSI: 91.9, ADX: 39.5, Vol: +68% above average)
A21: 29-05-2026 | B21: Satellite | C21: MAYURUNIQ | E21: Satellite | F21: Watchlist | G21: BUY | H21: Buy breakout (RSI: 79.5, ADX: 28.3, Vol: +83% above average)
A22: 29-05-2026 | B22: Satellite | C22: NGLFINE | E22: Satellite | F22: Watchlist | G22: BUY | H22: Buy breakout (RSI: 77.5, ADX: 65.9, Vol: +199% above average)
A23: 29-05-2026 | B23: Satellite | C23: SHILPAMED | E23: Satellite | F23: Watchlist | G23: BUY | H23: Buy breakout (RSI: 75.8, ADX: 37.8, Vol: +104% above average)
A24: 29-05-2026 | B24: Satellite | C24: SPARC | E24: Satellite | F24: Watchlist | G24: BUY | H24: Buy breakout (RSI: 75.3, ADX: 44.3, Vol: +511% above average)
A25: 29-05-2026 | B25: Satellite | C25: SUPRIYA | E25: Satellite | F25: Watchlist | G25: BUY | H25: Buy breakout (RSI: 78.9, ADX: 25.8, Vol: +420% above average)
A26: 29-05-2026 | B26: Satellite | C26: SUVEN | E26: Satellite | F26: Watchlist | G26: BUY | H26: Buy breakout (RSI: 76.7, ADX: 34.5, Vol: +34% above average)
A27: 29-05-2026 | B27: Satellite | C27: THERMAX | E27: Satellite | F27: Watchlist | G27: BUY | H27: Buy breakout (RSI: 79.8, ADX: 31.5, Vol: +52% above average) | I27: yes
A28: 46028 | B28: Satellite | C28: ABB | E28: Satellite | F28: Watchlist | G28: BUY | H28: Buy breakout (RSI: 66.3, ADX: 38.1, Vol: +50% above average)
A29: 46028 | B29: Satellite | C29: ADANIENSOL | E29: Satellite | F29: Watchlist | G29: BUY | H29: Buy breakout (RSI: 73.5, ADX: 33.0, Vol: +89% above average)
A30: 46028 | B30: Satellite | C30: CONFIPET | E30: Satellite | F30: Watchlist | G30: BUY | H30: Buy breakout (RSI: 74.6, ADX: 55.7, Vol: +12% above average)
A31: 46028 | B31: Satellite | C31: E2E | E31: Satellite | F31: Watchlist | G31: BUY | H31: Buy breakout (RSI: 70.5, ADX: 28.6, Vol: +78% above average)
A32: 46028 | B32: Satellite | C32: EXIDEIND | E32: Satellite | F32: Watchlist | G32: BUY | H32: Buy breakout (RSI: 63.5, ADX: 28.0, Vol: +239% above average)
A33: 46028 | B33: Satellite | C33: FCL | E33: Satellite | F33: Watchlist | G33: BUY | H33: Buy breakout (RSI: 76.4, ADX: 35.1, Vol: +468% above average)
A34: 46028 | B34: Satellite | C34: FINCABLES | E34: Satellite | F34: Watchlist | G34: BUY | H34: Buy breakout (RSI: 66.8, ADX: 34.8, Vol: +108% above average)
A35: 46028 | B35: Satellite | C35: MARKSANS | E35: Satellite | F35: Watchlist | G35: BUY | H35: Buy breakout (RSI: 75.4, ADX: 26.9, Vol: +720% above average)
A36: 46028 | B36: Satellite | C36: MOLDTKPAC | E36: Satellite | F36: Watchlist | G36: BUY | H36: Buy breakout (RSI: 63.7, ADX: 26.2, Vol: +8% above average)
A37: 46028 | B37: Satellite | C37: NETWEB | E37: Satellite | F37: Watchlist | G37: BUY | H37: Buy breakout (RSI: 65.9, ADX: 45.1, Vol: +156% above average)
A38: 46028 | B38: Satellite | C38: SKIPPER | E38: Satellite | F38: Watchlist | G38: BUY | H38: Buy breakout (RSI: 71.4, ADX: 31.9, Vol: +277% above average)
A39: 46028 | B39: Satellite | C39: SUVEN | E39: Satellite | F39: Watchlist | G39: BUY | H39: Buy breakout (RSI: 76.2, ADX: 34.5, Vol: +109% above average)
A40: 46028 | B40: Satellite | C40: TRITURBINE | E40: Satellite | F40: Watchlist | G40: BUY | H40: Buy breakout (RSI: 82.1, ADX: 26.6, Vol: +74% above average)

Sheet Raw_Tradebook
A1: Unnamed: 0.1 | B1: Symbol | C1: ISIN | D1: Trade Date | E1: Exchange | F1: Segment | G1: Series | H1: Trade Type | I1: Auction | J1: Quantity | K1: Price | L1: Trade ID | M1: Order ID | N1: Order Execution Time | O1: Unnamed: 0
B2: POLYCAB | C2: INE455K01017 | D2: 2025-09-08 | E2: NSE | F2: EQ | G2: EQ | H2: buy | I2: FALSE | J2: 13 | K2: 7343 | L2: 405271862 | M2: 1.2e+15 | N2: 2025-09-08T13:01:01
B3: CIPLA | C3: INE059A01026 | D3: 2025-09-08 | E3: NSE | F3: EQ | G3: EQ | H3: buy | I3: FALSE | J3: 64 | K3: 1548.9 | L3: 3877073 | M3: 1e+15 | N3: 2025-09-08T13:15:31
B4: HBLENGINE | C4: INE292B01021 | D4: 2025-09-08 | E4: NSE | F4: EQ | G4: EQ | H4: buy | I4: FALSE | J4: 7 | K4: 844.15 | L4: 205329072 | M4: 1.1e+15 | N4: 2025-09-08T13:22:33
B5: HBLENGINE | C5: INE292B01021 | D5: 2025-09-08 | E5: NSE | F5: EQ | G5: EQ | H5: buy | I5: FALSE | J5: 50 | K5: 844.15 | L5: 205330804 | M5: 1.1e+15 | N5: 2025-09-08T13:22:33
B6: HBLENGINE | C6: INE292B01021 | D6: 2025-09-08 | E6: NSE | F6: EQ | G6: EQ | H6: buy | I6: FALSE | J6: 4 | K6: 844.15 | L6: 205330817 | M6: 1.1e+15 | N6: 2025-09-08T13:22:33
B7: HBLENGINE | C7: INE292B01021 | D7: 2025-09-08 | E7: NSE | F7: EQ | G7: EQ | H7: buy | I7: FALSE | J7: 55 | K7: 844.15 | L7: 205331314 | M7: 1.1e+15 | N7: 2025-09-08T13:22:33
B8: SUPREMEIND | C8: INE195A01028 | D8: 2025-09-08 | E8: NSE | F8: EQ | G8: EQ | H8: buy | I8: FALSE | J8: 20 | K8: 4509 | L8: 605415434 | M8: 1.3e+15 | N8: 2025-09-08T13:36:34
B9: TITAN | C9: INE280A01028 | D9: 2025-09-08 | E9: NSE | F9: EQ | G9: EQ | H9: buy | I9: FALSE | J9: 11 | K9: 3662.7 | L9: 605630531 | M9: 1.3e+15 | N9: 2025-09-08T13:52:01
B10: TITAN | C10: INE280A01028 | D10: 2025-09-08 | E10: NSE | F10: EQ | G10: EQ | H10: buy | I10: FALSE | J10: 14 | K10: 3662.7 | L10: 605630530 | M10: 1.3e+15 | N10: 2025-09-08T13:52:01
B11: DMART | C11: INE192R01011 | D11: 2025-09-08 | E11: NSE | F11: EQ | G11: EQ | H11: buy | I11: FALSE | J11: 5 | K11: 4724.1001 | L11: 205904922 | M11: 1.1e+15 | N11: 2025-09-08T13:56:18
B12: DMART | C12: INE192R01011 | D12: 2025-09-08 | E12: NSE | F12: EQ | G12: EQ | H12: buy | I12: FALSE | J12: 1 | K12: 4724.1001 | L12: 205904923 | M12: 1.1e+15 | N12: 2025-09-08T13:56:18
B13: DMART | C13: INE192R01011 | D13: 2025-09-08 | E13: NSE | F13: EQ | G13: EQ | H13: buy | I13: FALSE | J13: 1 | K13: 4724 | L13: 205904921 | M13: 1.1e+15 | N13: 2025-09-08T13:56:18
... B161: DMART | C161: INE192R01011 | D161: 2025-11-11 | E161: NSE | F161: EQ | G161: EQ | H161: sell | I161: FALSE | J161: 19 | K161: 4056.8 | L161: 206418034 | M161: 1.1000001e+15 | N161: 2025-11-11T13:34:21
B162: METROPOLIS | D162: 2025-11-11 | E162: BSE | F162: EQ | G162: A | H162: sell | I162: FALSE | J162: 160 | K162: 482.775 | L162: 6267600 | M162: 1.7628443e+18 | N162: 2025-11-11T13:35:27
B163: METROPOLIS | D163: 2025-11-11 | E163: BSE | F163: EQ | G163: A | H163: sell | I163: FALSE | J163: 8 | K163: 482.3125 | L163: 6267800 | M163: 1.7628443e+18 | N163: 2025-11-11T13:35:27
B164: POLYCAB | C164: INE455K01017 | D164: 2025-11-13 | E164: NSE | F164: EQ | G164: EQ | H164: buy | I164: FALSE | J164: 5 | K164: 7775.5 | L164: 402401951 | M164: 1.2e+15 | N164: 2025-11-13T10:59:29
B165: POLYCAB | C165: INE455K01017 | D165: 2025-11-13 | E165: NSE | F165: EQ | G165: EQ | H165: buy | I165: FALSE | J165: 1 | K165: 7773.5 | L165: 402401948 | M165: 1.2e+15 | N165: 2025-11-13T10:59:29
B166: POLYCAB | C166: INE455K01017 | D166: 2025-11-13 | E166: NSE | F166: EQ | G166: EQ | H166: buy | I166: FALSE | J166: 1 | K166: 7775.5 | L166: 402401949 | M166: 1.2e+15 | N166: 2025-11-13T10:59:29
B167: POLYCAB | C167: INE455K01017 | D167: 2025-11-13 | E167: NSE | F167: EQ | G167: EQ | H167: buy | I167: FALSE | J167: 3 | K167: 7775.5 | L167: 402401950 | M167: 1.2e+15 | N167: 2025-11-13T10:59:29
B168: POLYCAB | C168: INE455K01017 | D168: 2025-11-13 | E168: NSE | F168: EQ | G168: EQ | H168: buy | I168: FALSE | J168: 2 | K168: 7776 | L168: 402401953 | M168: 1.2e+15 | N168: 2025-11-13T10:59:29
B169: PRECWIRE | C169: INE372C01037 | D169: 2025-11-14 | E169: NSE | F169: EQ | G169: EQ | H169: buy | I169: FALSE | J169: 1 | K169: 268.67 | L169: 406381643 | M169: 1.2000001e+15 | N169: 2025-11-14T15:19:43
B170: PRECWIRE | C170: INE372C01037 | D170: 2025-11-14 | E170: NSE | F170: EQ | G170: EQ | H170: buy | I170: FALSE | J170: 99 | K170: 268.67 | L170: 406381642 | M170: 1.2000001e+15 | N170: 2025-11-14T15:19:43
B171: BHARATFORG | D171: 2025-11-17 | E171: NSE | F171: EQ | G171: EQ | H171: buy | I171: FALSE | J171: 13 | K171: 1393.8 | L171: 2834568 | M171: 1e+15 | N171: 2025-11-17T11:53:38
B172: BHARATFORG | D172: 2025-11-17 | E172: NSE | F172: EQ | G172: EQ | H172: buy | I172: FALSE | J172: 23 | K172: 1393.8 | L172: 2834567 | M172: 1e+15 | N172: 2025-11-17T11:53:38
B173: TVSSRICHAK | D173: 2025-11-17 | E173: NSE | F173: EQ | G173: EQ | H173: buy | I173: FALSE | J173: 2 | K173: 4514.2998 | L173: 604224003 | M173: 1.3e+15 | N173: 2025-11-17T12:03:55
B174: TVSSRICHAK | D174: 2025-11-17 | E174: NSE | F174: EQ | G174: EQ | H174: buy | I174: FALSE | J174: 2 | K174: 4514.7002 | L174: 604224005 | M174: 1.3e+15 | N174: 2025-11-17T12:03:55
B175: TVSSRICHAK | D175: 2025-11-17 | E175: NSE | F175: EQ | G175: EQ | H175: buy | I175: FALSE | J175: 4 | K175: 4512.5 | L175: 604224002 | M175: 1.3e+15 | N175: 2025-11-17T12:03:55
B176: TVSSRICHAK | D176: 2025-11-17 | E176: NSE | F176: EQ | G176: EQ | H176: buy | I176: FALSE | J176: 3 | K176: 4514.3999 | L176: 604224004 | M176: 1.3e+15 | N176: 2025-11-17T12:03:55
B177: TVSSRICHAK | C177: INE421C01016 | D177: 2025-11-21 | E177: NSE | F177: EQ | G177: EQ | H177: buy | I177: FALSE | J177: 3 | K177: 4712.1001 | L177: 605255054 | M177: 1.3e+15 | N177: 2025-11-21T14:27:21
B178: TVSSRICHAK | C178: INE421C01016 | D178: 2025-11-21 | E178: NSE | F178: EQ | G178: EQ | H178: buy | I178: FALSE | J178: 4 | K178: 4712 | L178: 605255052 | M178: 1.3e+15 | N178: 2025-11-21T14:27:21
B179: TVSSRICHAK | C179: INE421C01016 | D179: 2025-11-21 | E179: NSE | F179: EQ | G179: EQ | H179: buy | I179: FALSE | J179: 2 | K179: 4712.1001 | L179: 605255053 | M179: 1.3e+15 | N179: 2025-11-21T14:27:21
B180: TVSSRICHAK | C180: INE421C01016 | D180: 2025-11-21 | E180: NSE | F180: EQ | G180: EQ | H180: buy | I180: FALSE | J180: 2 | K180: 4711.8999 | L180: 605255051 | M180: 1.3e+15 | N180: 2025-11-21T14:27:21
B181: FEDERALBNK | C181: INE171A01029 | D181: 2025-11-21 | E181: NSE | F181: EQ | G181: EQ | H181: buy | I181: FALSE | J181: 108 | K181: 246.27 | L181: 206412972 | M181: 1.1000001e+15 | N181: 2025-11-21T14:28:03
B182: FEDERALBNK | C182: INE171A01029 | D182: 2025-11-21 | E182: NSE | F182: EQ | G182: EQ | H182: buy | I182: FALSE | J182: 96 | K182: 246.28 | L182: 206412973 | M182: 1.1000001e+15 | N182: 2025-11-21T14:28:03
B183: FEDERALBNK | C183: INE171A01029 | D183: 2025-11-28 | E183: NSE | F183: EQ | G183: EQ | H183: buy | I183: FALSE | J183: 14 | K183: 257.71 | L183: 205976622 | M183: 1.1000001e+15 | N183: 2025-11-28T14:55:57
B184: FEDERALBNK | C184: INE171A01029 | D184: 2025-11-28 | E184: NSE | F184: EQ | G184: EQ | H184: buy | I184: FALSE | J184: 250 | K184: 257.7 | L184: 205976620 | M184: 1.1000001e+15 | N184: 2025-11-28T14:55:57
B185: FEDERALBNK | C185: INE171A01029 | D185: 2025-11-28 | E185: NSE | F185: EQ | G185: EQ | H185: buy | I185: FALSE | J185: 92 | K185: 257.7 | L185: 205976621 | M185: 1.1000001e+15 | N185: 2025-11-28T14:55:57
B186: FEDERALBNK | C186: INE171A01029 | D186: 2025-11-28 | E186: NSE | F186: EQ | G186: EQ | H186: buy | I186: FALSE | J186: 32 | K186: 257.7 | L186: 205976619 | M186: 1.1000001e+15 | N186: 2025-11-28T14:55:57
B187: GMRAIRPORT | C187: INE776C01039 | D187: 2025-11-28 | E187: NSE | F187: EQ | G187: EQ | H187: buy | I187: FALSE | J187: 677 | K187: 108.48 | L187: 206027992 | M187: 1.1000001e+15 | N187: 2025-11-28T14:58:37
...

Sheet Transaction
A1: Trade Date | B1: Symbol | C1: Trade Type | D1: Total_Quantity | E1: Average_Price | F1: Total_Value | G1: Tranches/Cheat
A2: 2025-09-08 | B2: POLYCAB | C2: buy | D2: 13 | E2: 7343 | F2: 95459 | G2: Tranch 1
A3: 2025-09-08 | B3: SUPREMEIND | C3: buy | D3: 20 | E3: 4509 | F3: 90180 | G3: Tranch 1
A4: 2025-09-08 | B4: DMART | C4: buy | D4: 19 | E4: 4724.03 | F4: 89756.6 | G4: Tranch 1
A5: 2025-09-08 | B5: CIPLA | C5: buy | D5: 64 | E5: 1548.9 | F5: 99129.6 | G5: Tranch 1
A6: 2025-09-08 | B6: METROPOLIS | C6: buy | D6: 168 | E6: 543 | F6: 91224 | G6: Tranch 1
A7: 2025-09-08 | B7: HBLENGINE | C7: buy | D7: 116 | E7: 844.15 | F7: 97921.4 | G7: Tranch 1
A8: 2025-09-08 | B8: TITAN | C8: buy | D8: 25 | E8: 3662.7 | F8: 91567.5 | G8: Tranch 1
A9: 2025-09-09 | B9: GMDCLTD | C9: buy | D9: 48 | E9: 517.1 | F9: 24820.8 | G9: Cheat 1
A10: 2025-09-09 | B10: UNOMINDA | C10: buy | D10: 37 | E10: 1289.2 | F10: 47700.4 | G10: Cheat 1
A11: 2025-09-09 | B11: PIDILITIND | C11: buy | D11: 60 | E11: 1562.4 | F11: 93744 | G11: Tranch 1
A12: 2025-09-09 | B12: AVANTEL | C12: buy | D12: 140 | E12: 175.36 | F12: 24550.4 | G12: Cheat 1
A13: 2025-09-15 | B13: CGPOWER | C13: buy | D13: 33 | E13: 785.35 | F13: 25916.55 | G13: Cheat 1
... A220: 2026-06-02 | B220: POLYCAB | C220: buy | D220: 3 | E220: 9432 | F220: 28296 | G220: Cheat 1

Sheet Current_Portfolio
A1: Symbol | B1: Cap | C1: TF_Sector | D1: TF_Classification | E1: Latest_Tranche | F1: Current_Quantity | G1: Average_Buy_Price | H1: Trend | I1: SL | J1: LTP_SL_Diff | K1: LTP_SL_Diff_Pct | L1: Invested_Value | M1: LTP | N1: Prev_Day_Close | O1: Prev_Week_Close | P1: EMA9 | Q1: EMA10 | R1: EMA11 | S1: EMA21 | T1: Current_Value | U1: Unrealized_PnL | V1: Return_Pct | W1: XIRR | X1: Holding_Period | Y1: Split_Info | Z1: Adj_Required | AA1: Prev_Month_Close
A2: ACUTAAS | B2: Small Cap | C2: Health / Pharma / Chem | D2: Core | E2: Cheat 2 | F2: 28 | G2: 2802.75 | H2: =IF(M2>N2, "▲", IF(M2<N2, "▼", "─")) -> ▲ | I2: 2522.47 | J2: =M2-I2 -> 613.23 | K2: =IF(M2>0, (M2-I2)/M2, 0) -> 0.19556399 | L2: 78477 | M2: =IFERROR(INDEX(Price_Update!$F:$F, MATCH(A2, Price_Update!$A:$A, 0)), 3135.7) -> 3135.7 | N2: =IFERROR(INDEX(Price_Update!$I:$I, MATCH(A2, Price_Update!$A:$A, 0)), 3037.6) -> 3037.6 | O2: 3132.5 | P2: 3017.01 | Q2: 3005.33 | R2: 2993.69 | S2: 2883.89 | T2: =F2*M2 -> 87799.6 | U2: =T2-L2 -> 9322.6 | V2: =IF(L2>0, U2/L2, 0) -> 0.11879404 | W2: 19.429565 | X2: 20 | Z2: No | AA2: 3132.5
A3: AIAENG | B3: Mid Cap | C3: Industrial | D3: Core | E3: Cheat 1 | F3: 6 | G3: 4554.1 | H3: =IF(M3>N3, "▲", IF(M3<N3, "▼", "─")) -> ▼ | I3: 4098.69 | J3: =M3-I3 -> 422.61 | K3: =IF(M3>0, (M3-I3)/M3, 0) -> 0.093470904 | L3: 27324.6 | M3: =IFERROR(INDEX(Price_Update!$F:$F, MATCH(A3, Price_Update!$A:$A, 0)), 4521.3) -> 4521.3 | N3: =IFERROR(INDEX(Price_Update!$I:$I, MATCH(A3, Price_Update!$A:$A, 0)), 4552.3) -> 4552.3 | O3: 4503.6 | P3: 4371 | Q3: 4348.63 | R3: 4327.86 | S3: 4184.18 | T3: =F3*M3 -> 27127.8 | U3: =T3-L3 -> -196.8 | V3: =IF(L3>0, U3/L3, 0) -> -0.0072023012 | W3: -0.73264563 | X3: 2 | Z3: No | AA3: 4503.6
A4: APARINDS | B4: Mid Cap | C4: Industrial | D4: Core | E4: Cheat 1 | F4: 4 | G4: 12829 | H4: =IF(M4>N4, "▲", IF(M4<N4, "▼", "─")) -> ▲ | I4: 11546.1 | J4: =M4-I4 -> 1991.9 | K4: =IF(M4>0, (M4-I4)/M4, 0) -> 0.14713399 | L4: 51316 | M4: =IFERROR(INDEX(Price_Update!$F:$F, MATCH(A4, Price_Update!$A:$A, 0)), 13538) -> 13538 | N4: =IFERROR(INDEX(Price_Update!$I:$I, MATCH(A4, Price_Update!$A:$A, 0)), 13270) -> 13270 | O4: 13118 | P4: 13088.93 | Q4: 13058.94 | R4: 13030.22 | S4: 12756.29 | T4: =F4*M4 -> 54152 | U4: =T4-L4 -> 2836 | V4: =IF(L4>0, U4/L4, 0) -> 0.055265414 | W4: 18343.72 | X4: 2 | Z4: No | AA4: 13118
A5: APLAPOLLO | B5: Mid Cap | C5: Industrial | D5: Core | E5: Tranch 2 | F5: 96 | G5: 2100.8 | H5: =IF(M5>N5, "▲", IF(M5<N5, "▼", "─")) -> ▲ | I5: 2237.6 | J5: =M5-I5 -> -432.2 | K5: =IF(M5>0, (M5-I5)/M5, 0) -> -0.23939293 | L5: 201676.8 | M5: =IFERROR(INDEX(Price_Update!$F:$F, MATCH(A5, Price_Update!$A:$A, 0)), 1805.4) -> 1805.4 | N5: =IFERROR(INDEX(Price_Update!$I:$I, MATCH(A5, Price_Update!$A:$A, 0)), 1769.2) -> 1769.2 | O5: 1831.1 | P5: 1829.68 | Q5: 1833.66 | R5: 1837.44 | S5: 1869.23 | T5: =F5*M5 -> 173318.4 | U5: =T5-L5 -> -28358.4 | V5: =IF(L5>0, U5/L5, 0) -> -0.1406131 | W5: -0.44076721 | X5: 115 | Z5: No | AA5: 1831.1
A6: BAJAJ-AUTO | B6: Large Cap | C6: Consumption | D6: Core | E6: Cheat 1 | F6: 3 | G6: 10344 | H6: =IF(M6>N6, "▲", IF(M6<N6, "▼", "─")) -> ▼ | I6: 9309.6 | J6: =M6-I6 -> 949.4 | K6: =IF(M6>0, (M6-I6)/M6, 0) -> 0.092543133 | L6: 31032 | M6: =IFERROR(INDEX(Price_Update!$F:$F, MATCH(A6, Price_Update!$A:$A, 0)), 10259) -> 10259 | N6: =IFERROR(INDEX(Price_Update!$I:$I, MATCH(A6, Price_Update!$A:$A, 0)), 10281) -> 10281 | O6: 10460 | P6: 10373.86 | Q6: 10370.84 | R6: 10365.91 | S6: 10262.22 | T6: =F6*M6 -> 30777 | U6: =T6-L6 -> -255 | V6: =IF(L6>0, U6/L6, 0) -> -0.0082173241 | W6: -0.77817294 | X6: 2 | Z6: No | AA6: 10460
A7: BSE | B7: Large Cap | C7: Finance | D7: Core | E7: Tranch 1 | F7: 30 | G7: 3359 | H7: =IF(M7>N7, "▲", IF(M7<N7, "▼", "─")) -> ▲ | I7: 3023.1 | J7: =M7-I7 -> 943 | K7: =IF(M7>0, (M7-I7)/M7, 0) -> 0.23776506 | L7: 100770 | M7: =IFERROR(INDEX(Price_Update!$F:$F, MATCH(A7, Price_Update!$A:$A, 0)), 3966.1) -> 3966.1 | N7: =IFERROR(INDEX(Price_Update!$I:$I, MATCH(A7, Price_Update!$A:$A, 0)), 3931.9) -> 3931.9 | O7: 4146.1 | P7: 4090.96 | Q7: 4092.78 | R7: 4092.22 | S7: 4017.35 | T7: =F7*M7 -> 118983 | U7: =T7-L7 -> 18213 | V7: =IF(L7>0, U7/L7, 0) -> 0.18073831 | W7: 0.8212997 | X7: 178 | Z7: No | AA7: 4146.1
A8: CAPLIPOINT | B8: Small Cap | C8: Health / Pharma / Chem | D8: Core | E8: Cheat 1 | F8: 15 | G8: 1972.4 | H8: =IF(M8>N8, "▲", IF(M8<N8, "▼", "─")) -> ▼ | I8: 1775.16 | J8: =M8-I8 -> 197.74 | K8: =IF(M8>0, (M8-I8)/M8, 0) -> 0.10022809 | L8: 29586 | M8: =IFERROR(INDEX(Price_Update!$F:$F, MATCH(A8, Price_Update!$A:$A, 0)), 1972.9) -> 1972.9 | N8: =IFERROR(INDEX(Price_Update!$I:$I, MATCH(A8, Price_Update!$A:$A, 0)), 1988.1) -> 1988.1 | O8: 2024.5 | P8: 1998.51 | Q8: 1996.32 | R8: 1993.43 | S8: 1949.65 | T8: =F8*M8 -> 29593.5 | U8: =T8-L8 -> 7.5 | V8: =IF(L8>0, U8/L8, 0) -> 0.00025349828 | W8: 0.047344143 | X8: 2 | Z8: No | AA8: 2024.5
A9: CARYSIL | B9: Small Cap | C9: Consumption | D9: Core | E9: Cheat 1 | F9: 27 | G9: 1101.3 | H9: =IF(M9>N9, "▲", IF(M9<N9, "▼", "─")) -> ▲ | I9: 991.17 | J9: =M9-I9 -> 146.83 | K9: =IF(M9>0, (M9-I9)/M9, 0) -> 0.1290246 | L9: 29735.1 | M9: =IFERROR(INDEX(Price_Update!$F:$F, MATCH(A9, Price_Update!$A:$A, 0)), 1138) -> 1138 | N9: =IFERROR(INDEX(Price_Update!$I:$I, MATCH(A9, Price_Update!$A:$A, 0)), 1113.5) -> 1113.5 | O9: 1077.55 | P9: 1082.69 | Q9: 1077.29 | R9: 1071.96 | S9: 1026.37 | T9: =F9*M9 -> 30726 | U9: =T9-L9 -> 990.9 | V9: =IF(L9>0, U9/L9, 0) -> 0.033324253 | W9: 395.44566 | X9: 2 | Z9: No | AA9: 1077.55
A10: CCL | B10: Small Cap | C10: Consumption | D10: Core | E10: Cheat 1 | F10: 49 | G10: 1033.16 | H10: =IF(M10>N10, "▲", IF(M10<N10, "▼", "─")) -> ▲ | I10: 929.84 | J10: =M10-I10 -> 148.36 | K10: =IF(M10>0, (M10-I10)/M10, 0) -> 0.1375997 | L10: 50624.84 | M10: =IFERROR(INDEX(Price_Update!$F:$F, MATCH(A10, Price_Update!$A:$A, 0)), 1078.2) -> 1078.2 | N10: =IFERROR(INDEX(Price_Update!$I:$I, MATCH(A10, Price_Update!$A:$A, 0)), 1070.5) -> 1070.5 | O10: 1053.8 | P10: 1073.76 | Q10: 1074.98 | R10: 1076.26 | S10: 1086.59 | T10: =F10*M10 -> 52831.8 | U10: =T10-L10 -> 2206.96 | V10: =IF(L10>0, U10/L10, 0) -> 0.043594409 | W10: 0.19607044 | X10: 87 | Z10: No | AA10: 1053.8
A11: CRAFTSMAN | B11: Small Cap | C11: Industrial | D11: Core | E11: Cheat 1 | F11: 6 | G11: 8958 | H11: =IF(M11>N11, "▲", IF(M11<N11, "▼", "─")) -> ▼ | I11: 8062.2 | J11: =M11-I11 -> 836.3 | K11: =IF(M11>0, (M11-I11)/M11, 0) -> 0.093982132 | L11: 53748 | M11: =IFERROR(INDEX(Price_Update!$F:$F, MATCH(A11, Price_Update!$A:$A, 0)), 8898.5) -> 8898.5 | N11: =IFERROR(INDEX(Price_Update!$I:$I, MATCH(A11, Price_Update!$A:$A, 0)), 8979) -> 8979 | O11: 9074 | P11: 8799.61 | Q11: 8781.74 | R11: 8763.49 | S11: 8567.42 | T11: =F11*M11 -> 53391 | U11: =T11-L11 -> -357 | V11: =IF(L11>0, U11/L11, 0) -> -0.0066421076 | W11: -0.70365421 | X11: 2 | Z11: No | AA11: 9074
A12: FCL | B12: Small Cap | C12: Health / Pharma / Chem | D12: Core | E12: Cheat 1 | F12: 685 | G12: 42.36 | H12: =IF(M12>N12, "▲", IF(M12<N12, "▼", "─")) -> ▲ | I12: 38.12 | J12: =M12-I12 -> 5.42 | K12: =IF(M12>0, (M12-I12)/M12, 0) -> 0.12448323 | L12: 29016.6 | M12: =IFERROR(INDEX(Price_Update!$F:$F, MATCH(A12, Price_Update!$A:$A, 0)), 43.54) -> 43.54 | N12: =IFERROR(INDEX(Price_Update!$I:$I, MATCH(A12, Price_Update!$A:$A, 0)), 42.36) -> 42.36 | O12: 39.99 | P12: 39.32 | Q12: 38.85 | R12: 38.39 | S12: 34.67 | T12: =F12*M12 -> 29824.9 | U12: =T12-L12 -> 808.3 | V12: =IF(L12>0, U12/L12, 0) -> 0.027856468 | W12: 149.54848 | X12: 2 | Z12: No | AA12: 39.99
A13: FEDERALBNK | B13: Mid Cap | C13: Finance | D13: Core | E13: Tranch 3 | F13: 1172 | G13: 256.22 | H13: =IF(M13>N13, "▲", IF(M13<N13, "▼", "─")) -> ▲ | I13: 260.1 | J13: =M13-I13 -> 40.95 | K13: =IF(M13>0, (M13-I13)/M13, 0) -> 0.13602392 | L13: 300289.84 | M13: =IFERROR(INDEX(Price_Update!$F:$F, MATCH(A13, Price_Update!$A:$A, 0)), 301.05) -> 301.05 | N13: =IFERROR(INDEX(Price_Update!$I:$I, MATCH(A13, Price_Update!$A:$A, 0)), 293.05) -> 293.05 | O13: 288.95 | P13: 291.55 | Q13: 291.23 | R13: 290.95 | S13: 289.39 | T13: =F13*M13 -> 352830.6 | U13: =T13-L13 -> 52540.76 | V13: =IF(L13>0, U13/L13, 0) -> 0.17496683 | W13: 0.3934974 | X13: 213 | Z13: No | AA13: 288.95
A14: GVT&D | B14: Large Cap | C14: Consumption | D14: Core | E14: Tranch 2 | F14: 55 | G14: 4155.85 | H14: =IF(M14>N14, "▲", IF(M14<N14, "▼", "─")) -> ▲ | I14: 3676.8 | J14: =M14-I14 -> 1287.7 | K14: =IF(M14>0, (M14-I14)/M14, 0) -> 0.25938161 | L14: 228571.75 | M14: =IFERROR(INDEX(Price_Update!$F:$F, MATCH(A14, Price_Update!$A:$A, 0)), 4964.5) -> 4964.5 | N14: =IFERROR(INDEX(Price_Update!$I:$I, MATCH(A14, Price_Update!$A:$A, 0)), 4781) -> 4781 | O14: 5148.6 | P14: 4870.62 | Q14: 4858.02 | R14: 4845.06 | S14: 4717.29 | T14: =F14*M14 -> 273047.5 | U14: =T14-L14 -> 44475.75 | V14: =IF(L14>0, U14/L14, 0) -> 0.19458113 | W14: 2.6305917 | X14: 87 | Z14: No | AA14: 5148.6
A15: HBLENGINE | B15: Small Cap | C15: Industrial | D15: Core | E15: Cheat 1 | F15: 37 | G15: 865.69 | H15: =IF(M15>N15, "▲", IF(M15<N15, "▼", "─")) -> ▼ | I15: 844.15 | J15: =M15-I15 -> -57.9 | K15: =IF(M15>0, (M15-I15)/M15, 0) -> -0.0736407 | L15: 32030.53 | M15: =IFERROR(INDEX(Price_Update!$F:$F, MATCH(A15, Price_Update!$A:$A, 0)), 786.25) -> 786.25 | N15: =IFERROR(INDEX(Price_Update!$I:$I, MATCH(A15, Price_Update!$A:$A, 0)), 802.7) -> 802.7 | O15: 822.6 | P15: 796.93 | Q15: 796.51 | R15: 796.13 | S15: 791.88 | T15: =F15*M15 -> 29091.25 | U15: =T15-L15 -> -2939.28 | V15: =IF(L15>0, U15/L15, 0) -> -0.091764951 | W15: -0.44866775 | X15: 2 | Z15: No | AA15: 822.6
A16: HBLENGINE | B16: Small Cap | C16: Industrial | D16: Core | E16: Cheat 1 | F16: 37 | G16: 865.69 | H16: =IF(M16>N16, "▲", IF(M16<N16, "▼", "─")) -> ▼ | I16: 844.15 | J16: =M16-I16 -> -57.9 | K16: =IF(M16>0, (M16-I16)/M16, 0) -> -0.0736407 | L16: 32030.53 | M16: =IFERROR(INDEX(Price_Update!$F:$F, MATCH(A16, Price_Update!$A:$A, 0)), 786.25) -> 786.25 | N16: =IFERROR(INDEX(Price_Update!$I:$I, MATCH(A16, Price_Update!$A:$A, 0)), 802.7) -> 802.7 | O16: 822.6 | P16: 796.93 | Q16: 796.51 | R16: 796.13 | S16: 791.88 | T16: =F16*M16 -> 29091.25 | U16: =T16-L16 -> -2939.28 | V16: =IF(L16>0, U16/L16, 0) -> -0.091764951 | W16: -0.44866775 | X16: 2 | Z16: No | AA16: 822.6
A17: KEI | B17: Mid Cap | C17: Consumption | D17: Core | E17: Cheat 1 | F17: 6 | G17: 5189 | H17: =IF(M17>N17, "▲", IF(M17<N17, "▼", "─")) -> ▼ | I17: 4670.1 | J17: =M17-I17 -> 551.9 | K17: =IF(M17>0, (M17-I17)/M17, 0) -> 0.10568748 | L17: 31134 | M17: =IFERROR(INDEX(Price_Update!$F:$F, MATCH(A17, Price_Update!$A:$A, 0)), 5222) -> 5222 | N17: =IFERROR(INDEX(Price_Update!$I:$I, MATCH(A17, Price_Update!$A:$A, 0)), 5261.5) -> 5261.5 | O17: 5267.5 | P17: 5252.56 | Q17: 5248.07 | R17: 5242.67 | S17: 5164.36 | T17: =F17*M17 -> 31332 | U17: =T17-L17 -> 198 | V17: =IF(L17>0, U17/L17, 0) -> 0.0063596069 | W17: 2.1802292 | X17: 2 | Z17: No | AA17: 5267.5
A18: KRISHANA | B18: Small Cap | C18: Health / Pharma / Chem | D18: Core | E18: Cheat 1 | F18: 43 | G18: 679.8 | H18: =IF(M18>N18, "▲", IF(M18<N18, "▼", "─")) -> ▼ | I18: 611.82 | J18: =M18-I18 -> 70.83 | K18: =IF(M18>0, (M18-I18)/M18, 0) -> 0.10375742 | L18: 29231.4 | M18: =IFERROR(INDEX(Price_Update!$F:$F, MATCH(A18, Price_Update!$A:$A, 0)), 682.65) -> 682.65 | N18: =IFERROR(INDEX(Price_Update!$I:$I, MATCH(A18, Price_Update!$A:$A, 0)), 686.45) -> 686.45 | O18: 668.1 | P18: 678.66 | Q18: 678.16 | R18: 677.6 | S18: 667.87 | T18: =F18*M18 -> 29353.95 | U18: =T18-L18 -> 122.55 | V18: =IF(L18>0, U18/L18, 0) -> 0.0041924095 | W18: 1.1458063 | X18: 2 | Z18: No | AA18: 668.1
A19: LALPATHLAB | B19: Small Cap | C19: Health / Pharma / Chem | D19: Core | E19: Cheat 1 | F19: 18 | G19: 1562.2 | H19: =IF(M19>N19, "▲", IF(M19<N19, "▼", "─")) -> ▲ | I19: 1405.98 | J19: =M19-I19 -> 163.62 | K19: =IF(M19>0, (M19-I19)/M19, 0) -> 0.10424312 | L19: 28119.6 | M19: =IFERROR(INDEX(Price_Update!$F:$F, MATCH(A19, Price_Update!$A:$A, 0)), 1569.6) -> 1569.6 | N19: =IFERROR(INDEX(Price_Update!$I:$I, MATCH(A19, Price_Update!$A:$A, 0)), 1561) -> 1561 | O19: 1607.4 | P19: 1594.68 | Q19: 1595.96 | R19: 1596.63 | S19: 1583.38 | T19: =F19*M19 -> 28252.8 | U19: =T19-L19 -> 133.2 | V19: =IF(L19>0, U19/L19, 0) -> 0.0047369095 | W19: 1.3689455 | X19: 2 | Z19: No | AA19: 1607.4
A20: M&M | B20: Large Cap | C20: Industrial | D20: Core | E20: Cheat 1 | F20: 16 | G20: 3127 | H20: =IF(M20>N20, "▲", IF(M20<N20, "▼", "─")) -> ▲ | I20: 2814.3 | J20: =M20-I20 -> 196.8 | K20: =IF(M20>0, (M20-I20)/M20, 0) -> 0.065358175 | L20: 50032 | M20: =IFERROR(INDEX(Price_Update!$F:$F, MATCH(A20, Price_Update!$A:$A, 0)), 3011.1) -> 3011.1 | N20: =IFERROR(INDEX(Price_Update!$I:$I, MATCH(A20, Price_Update!$A:$A, 0)), 2998.3) -> 2998.3 | O20: 3045.6 | P20: 3052.89 | Q20: 3058.27 | R20: 3063.24 | S20: 3096.59 | T20: =F20*M20 -> 48177.6 | U20: =T20-L20 -> -1854.4 | V20: =IF(L20>0, U20/L20, 0) -> -0.037064279 | W20: -0.4980613 | X20: 20 | Z20: No | AA20: 3045.6
A21: METROPOLIS | B21: Small Cap | C21: Health / Pharma / Chem | D21: Core | E21: Cheat 1 | F21: 54 | G21: 544.58 | H21: =IF(M21>N21, "▲", IF(M21<N21, "▼", "─")) -> ▼ | I21: 490.12 | J21: =M21-I21 -> 46.03 | K21: =IF(M21>0, (M21-I21)/M21, 0) -> 0.08585284 | L21: 29407.32 | M21: =IFERROR(INDEX(Price_Update!$F:$F, MATCH(A21, Price_Update!$A:$A, 0)), 536.15) -> 536.15 | N21: =IFERROR(INDEX(Price_Update!$I:$I, MATCH(A21, Price_Update!$A:$A, 0)), 541.5) -> 541.5 | O21: 555.35 | P21: 536.86 | Q21: 536.11 | R21: 535.32 | S21: 526.08 | T21: =F21*M21 -> 28952.1 | U21: =T21-L21 -> -455.22 | V21: =IF(L21>0, U21/L21, 0) -> -0.015479819 | W21: -0.52044263 | X21: 2 | Y21: 4:1 Split on 2026-03-20 | Z21: No | AA21: 555.35
A22: METROPOLIS | B22: Small Cap | C22: Health / Pharma / Chem | D22: Core | E22: Cheat 1 | F22: 54 | G22: 544.58 | H22: =IF(M22>N22, "▲", IF(M22<N22, "▼", "─")) -> ▼ | I22: 490.12 | J22: =M22-I22 -> 46.03 | K22: =IF(M22>0, (M22-I22)/M22, 0) -> 0.08585284 | L22: 29407.32 | M22: =IFERROR(INDEX(Price_Update!$F:$F, MATCH(A22, Price_Update!$A:$A, 0)), 536.15) -> 536.15 | N22: =IFERROR(INDEX(Price_Update!$I:$I, MATCH(A22, Price_Update!$A:$A, 0)), 541.5) -> 541.5 | O22: 555.35 | P22: 536.86 | Q22: 536.11 | R22: 535.32 | S22: 526.08 | T22: =F22*M22 -> 28952.1 | U22: =T22-L22 -> -455.22 | V22: =IF(L22>0, U22/L22, 0) -> -0.015479819 | W22: -0.52044263 | X22: 2 | Y22: 4:1 Split on 2026-03-20 | Z22: No | AA22: 555.35
A23: NAVINFLUOR | B23: Mid Cap | C23: Health / Pharma / Chem | D23: Core | E23: Cheat 1 | F23: 4 | G23: 7050 | H23: =IF(M23>N23, "▲", IF(M23<N23, "▼", "─")) -> ▼ | I23: 6345 | J23: =M23-I23 -> 690.5 | K23: =IF(M23>0, (M23-I23)/M23, 0) -> 0.098145121 | L23: 28200 | M23: =IFERROR(INDEX(Price_Update!$F:$F, MATCH(A23, Price_Update!$A:$A, 0)), 7035.5) -> 7035.5 | N23: =IFERROR(INDEX(Price_Update!$I:$I, MATCH(A23, Price_Update!$A:$A, 0)), 7052) -> 7052 | O23: 7129 | P23: 7108.64 | Q23: 7107.95 | R23: 7105.49 | S23: 7029.6 | T23: =F23*M23 -> 28142 | U23: =T23-L23 -> -58 | V23: =IF(L23>0, U23/L23, 0) -> -0.0020567376 | W23: -0.31321991 | X23: 2 | Z23: No | AA23: 7129
A24: NGLFINE | B24: Small Cap | C24: Health / Pharma / Chem | D24: Core | E24: Cheat 1 | F24: 11 | G24: 2660 | H24: =IF(M24>N24, "▲", IF(M24<N24, "▼", "─")) -> ▼ | I24: 2394 | J24: =M24-I24 -> 251.1 | K24: =IF(M24>0, (M24-I24)/M24, 0) -> 0.094930248 | L24: 29260 | M24: =IFERROR(INDEX(Price_Update!$F:$F, MATCH(A24, Price_Update!$A:$A, 0)), 2645.1) -> 2645.1 | N24: =IFERROR(INDEX(Price_Update!$I:$I, MATCH(A24, Price_Update!$A:$A, 0)), 2654.5) -> 2654.5 | O24: 2785.1 | P24: 2655.07 | Q24: 2644.51 | R24: 2633.8 | S24: 2542.03 | T24: =F24*M24 -> 29096.1 | U24: =T24-L24 -> -163.9 | V24: =IF(L24>0, U24/L24, 0) -> -0.0056015038 | W24: -0.64125674 | X24: 2 | Z24: No | AA24: 2785.1
A25: NH | B25: Mid Cap | C25: Health / Pharma / Chem | D25: Core | E25: Cheat 1 | F25: 15 | G25: 1910.65 | H25: =IF(M25>N25, "▲", IF(M25<N25, "▼", "─")) -> ▲ | I25: 1719.59 | J25: =M25-I25 -> 261.01 | K25: =IF(M25>0, (M25-I25)/M25, 0) -> 0.1317833 | L25: 28659.75 | M25: =IFERROR(INDEX(Price_Update!$F:$F, MATCH(A25, Price_Update!$A:$A, 0)), 1980.6) -> 1980.6 | N25: =IFERROR(INDEX(Price_Update!$I:$I, MATCH(A25, Price_Update!$A:$A, 0)), 1934.2) -> 1934.2 | O25: 1894 | P25: 1920.45 | Q25: 1917.04 | R25: 1913.73 | S25: 1884.13 | T25: =F25*M25 -> 29709 | U25: =T25-L25 -> 1049.25 | V25: =IF(L25>0, U25/L25, 0) -> 0.036610578 | W25: 706.93251 | X25: 2 | Z25: No | AA25: 1894
A26: OFSS | B26: Mid Cap | C26: Technology | D26: Core | E26: Cheat 1 | F26: 3 | G26: 10301 | H26: =IF(M26>N26, "▲", IF(M26<N26, "▼", "─")) -> ▼ | I26: 9270.9 | J26: =M26-I26 -> 726.6 | K26: =IF(M26>0, (M26-I26)/M26, 0) -> 0.07267817 | L26: 30903 | M26: =IFERROR(INDEX(Price_Update!$F:$F, MATCH(A26, Price_Update!$A:$A, 0)), 9997.5) -> 9997.5 | N26: =IFERROR(INDEX(Price_Update!$I:$I, MATCH(A26, Price_Update!$A:$A, 0)), 10344.5) -> 10344.5 | O26: 9964 | P26: 10006.7 | Q26: 9977.64 | R26: 9948.04 | S26: 9632.57 | T26: =F26*M26 -> 29992.5 | U26: =T26-L26 -> -910.5 | V26: =IF(L26>0, U26/L26, 0) -> -0.029463159 | W26: 9.9999993 | X26: 2 | Z26: No | AA26: 9964
A27: POLYCAB | B27: Large Cap | C27: Consumption | D27: Core | E27: Tranch 4 | F27: 53 | G27: 7825.34 | H27: =IF(M27>N27, "▲", IF(M27<N27, "▼", "─")) -> ▲ | I27: 9146.72 | J27: =M27-I27 -> 424.78 | K27: =IF(M27>0, (M27-I27)/M27, 0) -> 0.044379669 | L27: 414743.02 | M27: =IFERROR(INDEX(Price_Update!$F:$F, MATCH(A27, Price_Update!$A:$A, 0)), 9571.5) -> 9571.5 | N27: =IFERROR(INDEX(Price_Update!$I:$I, MATCH(A27, Price_Update!$A:$A, 0)), 9531.5) -> 9531.5 | O27: 9477.5 | P27: 9447.26 | Q27: 9425.02 | R27: 9401.71 | S27: 9146.72 | T27: =F27*M27 -> 507289.5 | U27: =T27-L27 -> 92546.48 | V27: =IF(L27>0, U27/L27, 0) -> 0.22314174 | W27: 0.47606603 | X27: 269 | Z27: No | AA27: 9477.5
A28: POWERINDIA | B28: Large Cap | C28: Industrial | D28: Core | E28: Cheat 1 | F28: 1 | G28: 35105 | H28: =IF(M28>N28, "▲", IF(M28<N28, "▼", "─")) -> ▲ | I28: 31594.5 | J28: =M28-I28 -> 3595.5 | K28: =IF(M28>0, (M28-I28)/M28, 0) -> 0.10217391 | L28: 35105 | M28: =IFERROR(INDEX(Price_Update!$F:$F, MATCH(A28, Price_Update!$A:$A, 0)), 35190) -> 35190 | N28: =IFERROR(INDEX(Price_Update!$I:$I, MATCH(A28, Price_Update!$A:$A, 0)), 35105) -> 35105 | O28: 38445 | P28: 35923.08 | Q28: 35858.87 | R28: 35784.45 | S28: 34811.97 | T28: =F28*M28 -> 35190 | U28: =T28-L28 -> 85 | V28: =IF(L28>0, U28/L28, 0) -> 0.0024213075 | W28: 0.5548118 | X28: 2 | Z28: No | AA28: 38445
A29: PSPPROJECT | B29: Small Cap | C29: Industrial | D29: Core | E29: Cheat 1 | F29: 35 | G29: 838.6 | H29: =IF(M29>N29, "▲", IF(M29<N29, "▼", "─")) -> ▼ | I29: 754.74 | J29: =M29-I29 -> 65.31 | K29: =IF(M29>0, (M29-I29)/M29, 0) -> 0.079641485 | L29: 29351 | M29: =IFERROR(INDEX(Price_Update!$F:$F, MATCH(A29, Price_Update!$A:$A, 0)), 820.05) -> 820.05 | N29: =IFERROR(INDEX(Price_Update!$I:$I, MATCH(A29, Price_Update!$A:$A, 0)), 842.65) -> 842.65 | O29: 854.7 | P29: 823.38 | Q29: 821.39 | R29: 819.46 | S29: 801.95 | T29: =F29*M29 -> 28701.75 | U29: =T29-L29 -> -649.25 | V29: =IF(L29>0, U29/L29, 0) -> -0.0221202 | W29: -0.98313062 | X29: 2 | Z29: No | AA29: 854.7
A30: RAINBOW | B30: Small Cap | C30: Health / Pharma / Chem | D30: Core | E30: Cheat 1 | F30: 21 | G30: 1330.9 | H30: =IF(M30>N30, "▲", IF(M30<N30, "▼", "─")) -> ▲ | I30: 1197.81 | J30: =M30-I30 -> 156.39 | K30: =IF(M30>0, (M30-I30)/M30, 0) -> 0.11548516 | L30: 27948.9 | M30: =IFERROR(INDEX(Price_Update!$F:$F, MATCH(A30, Price_Update!$A:$A, 0)), 1354.2) -> 1354.2 | N30: =IFERROR(INDEX(Price_Update!$I:$I, MATCH(A30, Price_Update!$A:$A, 0)), 1341.4) -> 1341.4 | O30: 1380.3 | P30: 1356.91 | Q30: 1355.6 | R30: 1354.1 | S30: 1335.2 | T30: =F30*M30 -> 28438.2 | U30: =T30-L30 -> 489.3 | V30: =IF(L30>0, U30/L30, 0) -> 0.01750695 | W30: 22.745026 | X30: 2 | Z30: No | AA30: 1380.3
A31: SBCL | B31: Small Cap | C31: Industrial | D31: Core | E31: Cheat 1 | F31: 40 | G31: 729.68 | H31: =IF(M31>N31, "▲", IF(M31<N31, "▼", "─")) -> ▼ | I31: 656.71 | J31: =M31-I31 -> 67.19 | K31: =IF(M31>0, (M31-I31)/M31, 0) -> 0.092816687 | L31: 29187.2 | M31: =IFERROR(INDEX(Price_Update!$F:$F, MATCH(A31, Price_Update!$A:$A, 0)), 723.9) -> 723.9 | N31: =IFERROR(INDEX(Price_Update!$I:$I, MATCH(A31, Price_Update!$A:$A, 0)), 734.55) -> 734.55 | O31: 740 | P31: 719.62 | Q31: 716.01 | R31: 712.29 | S31: 676.01 | T31: =F31*M31 -> 28956 | U31: =T31-L31 -> -231.2 | V31: =IF(L31>0, U31/L31, 0) -> -0.0079212806 | W31: -0.7659019 | X31: 2 | Z31: No | AA31: 740
A32: SOLARINDS | B32: Large Cap | C32: Industrial | D32: Core | E32: Cheat 2 | F32: 4 | G32: 15640 | H32: =IF(M32>N32, "▲", IF(M32<N32, "▼", "─")) -> ▲ | I32: 14076 | J32: =M32-I32 -> 4501 | K32: =IF(M32>0, (M32-I32)/M32, 0) -> 0.24228885 | L32: 62560 | M32: =IFERROR(INDEX(Price_Update!$F:$F, MATCH(A32, Price_Update!$A:$A, 0)), 18577) -> 18577 | N32: =IFERROR(INDEX(Price_Update!$I:$I, MATCH(A32, Price_Update!$A:$A, 0)), 18386) -> 18386 | O32: 18247 | P32: 18288.93 | Q32: 18239.49 | R32: 18186.03 | S32: 17581.98 | T32: =F32*M32 -> 74308 | U32: =T32-L32 -> 11748 | V32: =IF(L32>0, U32/L32, 0) -> 0.18778772 | W32: 4.7169008 | X32: 76 | Z32: No | AA32: 18247
A33: SOLARINDS | B33: Large Cap | C33: Industrial | D33: Core | E33: Cheat 2 | F33: 4 | G33: 15640 | H33: =IF(M33>N33, "▲", IF(M33<N33, "▼", "─")) -> ▲ | I33: 14076 | J33: =M33-I33 -> 4501 | K33: =IF(M33>0, (M33-I33)/M33, 0) -> 0.24228885 | L33: 62560 | M33: =IFERROR(INDEX(Price_Update!$F:$F, MATCH(A33, Price_Update!$A:$A, 0)), 18577) -> 18577 | N33: =IFERROR(INDEX(Price_Update!$I:$I, MATCH(A33, Price_Update!$A:$A, 0)), 18386) -> 18386 | O33: 18247 | P33: 18288.93 | Q33: 18239.49 | R33: 18186.03 | S33: 17581.98 | T33: =F33*M33 -> 74308 | U33: =T33-L33 -> 11748 | V33: =IF(L33>0, U33/L33, 0) -> 0.18778772 | W33: 4.7169008 | X33: 76 | Z33: No | AA33: 18247
A34: SYRMA | B34: Small Cap | C34: Industrial | D34: Core | E34: Cheat 1 | F34: 26 | G34: 1152.9 | H34: =IF(M34>N34, "▲", IF(M34<N34, "▼", "─")) -> ▲ | I34: 1037.61 | J34: =M34-I34 -> 157.69 | K34: =IF(M34>0, (M34-I34)/M34, 0) -> 0.13192504 | L34: 29975.4 | M34: =IFERROR(INDEX(Price_Update!$F:$F, MATCH(A34, Price_Update!$A:$A, 0)), 1195.3) -> 1195.3 | N34: =IFERROR(INDEX(Price_Update!$I:$I, MATCH(A34, Price_Update!$A:$A, 0)), 1166.8) -> 1166.8 | O34: 1088.55 | P34: 1105.51 | Q34: 1100.18 | R34: 1095.42 | S34: 1060.51 | T34: =F34*M34 -> 31077.8 | U34: =T34-L34 -> 1102.4 | V34: =IF(L34>0, U34/L34, 0) -> 0.036776824 | W34: 727.72498 | X34: 2 | Z34: No | AA34: 1088.55
A35: TDPOWERSYS | B35: Small Cap | C35: Industrial | D35: Core | E35: Tranch 3 | F35: 321 | G35: 950.19 | H35: =IF(M35>N35, "▲", IF(M35<N35, "▼", "─")) -> ▲ | I35: 935.17 | J35: =M35-I35 -> 351.13 | K35: =IF(M35>0, (M35-I35)/M35, 0) -> 0.27297676 | L35: 305010.99 | M35: =IFERROR(INDEX(Price_Update!$F:$F, MATCH(A35, Price_Update!$A:$A, 0)), 1286.3) -> 1286.3 | N35: =IFERROR(INDEX(Price_Update!$I:$I, MATCH(A35, Price_Update!$A:$A, 0)), 1235) -> 1235 | O35: 1318.6 | P35: 1280.77 | Q35: 1279.8 | R35: 1278.28 | S35: 1246.07 | T35: =F35*M35 -> 412902.3 | U35: =T35-L35 -> 107891.31 | V35: =IF(L35>0, U35/L35, 0) -> 0.35372925 | W35: 4.2247996 | X35: 112 | Z35: No | AA35: 1318.6
A36: TIMKEN | B36: Small Cap | C36: Industrial | D36: Core | E36: Cheat 1 | F36: 8 | G36: 3520.1 | H36: =IF(M36>N36, "▲", IF(M36<N36, "▼", "─")) -> ▼ | I36: 3168.09 | J36: =M36-I36 -> 323.81 | K36: =IF(M36>0, (M36-I36)/M36, 0) -> 0.092731751 | L36: 28160.8 | M36: =IFERROR(INDEX(Price_Update!$F:$F, MATCH(A36, Price_Update!$A:$A, 0)), 3491.9) -> 3491.9 | N36: =IFERROR(INDEX(Price_Update!$I:$I, MATCH(A36, Price_Update!$A:$A, 0)), 3529.2) -> 3529.2 | O36: 3630.4 | P36: 3571.05 | Q36: 3572.74 | R36: 3573.63 | S36: 3562.31 | T36: =F36*M36 -> 27935.2 | U36: =T36-L36 -> -225.6 | V36: =IF(L36>0, U36/L36, 0) -> -0.008011136 | W36: -0.76959698 | X36: 2 | Z36: No | AA36: 3630.4
A37: TIPSMUSIC | B37: Small Cap | C37: Technology | D37: Core | E37: Cheat 1 | F37: 43 | G37: 663.75 | H37: =IF(M37>N37, "▲", IF(M37<N37, "▼", "─")) -> ▼ | I37: 597.38 | J37: =M37-I37 -> 62.47 | K37: =IF(M37>0, (M37-I37)/M37, 0) -> 0.094673032 | L37: 28541.25 | M37: =IFERROR(INDEX(Price_Update!$F:$F, MATCH(A37, Price_Update!$A:$A, 0)), 659.85) -> 659.85 | N37: =IFERROR(INDEX(Price_Update!$I:$I, MATCH(A37, Price_Update!$A:$A, 0)), 672.3) -> 672.3 | O37: 662.45 | P37: 661.49 | Q37: 660.96 | R37: 660.38 | S37: 651.86 | T37: =F37*M37 -> 28373.55 | U37: =T37-L37 -> -167.7 | V37: =IF(L37>0, U37/L37, 0) -> -0.0058757062 | W37: -0.65886572 | X37: 2 | Z37: No | AA37: 662.45
A38: TRITURBINE | B38: Small Cap | C38: Industrial | D38: Core | E38: Cheat 2 | F38: 114 | G38: 690.34 | H38: =IF(M38>N38, "▲", IF(M38<N38, "▼", "─")) -> ▼ | I38: 621.31 | J38: =M38-I38 -> 47.54 | K38: =IF(M38>0, (M38-I38)/M38, 0) -> 0.071077222 | L38: 78698.76 | M38: =IFERROR(INDEX(Price_Update!$F:$F, MATCH(A38, Price_Update!$A:$A, 0)), 668.85) -> 668.85 | N38: =IFERROR(INDEX(Price_Update!$I:$I, MATCH(A38, Price_Update!$A:$A, 0)), 689.25) -> 689.25 | O38: 741.5 | P38: 687.91 | Q38: 685.59 | R38: 683 | S38: 653.74 | T38: =F38*M38 -> 76248.9 | U38: =T38-L38 -> -2449.86 | V38: =IF(L38>0, U38/L38, 0) -> -0.031129588 | W38: -0.98745249 | X38: 3 | Z38: No | AA38: 741.5
A39: VBL | B39: Large Cap | C39: Consumption | D39: Core | E39: Cheat 1 | F39: 55 | G39: 533.75 | H39: =IF(M39>N39, "▲", IF(M39<N39, "▼", "─")) -> ▼ | I39: 480.38 | J39: =M39-I39 -> 53.02 | K39: =IF(M39>0, (M39-I39)/M39, 0) -> 0.099400075 | L39: 29356.25 | M39: =IFERROR(INDEX(Price_Update!$F:$F, MATCH(A39, Price_Update!$A:$A, 0)), 533.4) -> 533.4 | N39: =IFERROR(INDEX(Price_Update!$I:$I, MATCH(A39, Price_Update!$A:$A, 0)), 537) -> 537 | O39: 528 | P39: 529.39 | Q39: 528.6 | R39: 527.77 | S39: 518.34 | T39: =F39*M39 -> 29337 | U39: =T39-L39 -> -19.25 | V39: =IF(L39>0, U39/L39, 0) -> -0.0006557377 | W39: -0.11282355 | X39: 2 | Z39: No | AA39: 528
A40: ADANIENT | B40: Large Cap | C40: Industrial | D40: Satellite | E40: Tranch 1 | F40: 36 | G40: 2834.43 | H40: =IF(M40>N40, "▲", IF(M40<N40, "▼", "─")) -> ▼ | I40: 2550.99 | J40: =M40-I40 -> 374.61 | K40: =IF(M40>0, (M40-I40)/M40, 0) -> 0.12804553 | L40: 102039.48 | M40: =IFERROR(INDEX(Price_Update!$F:$F, MATCH(A40, Price_Update!$A:$A, 0)), 2925.6) -> 2925.6 | N40: =IFERROR(INDEX(Price_Update!$I:$I, MATCH(A40, Price_Update!$A:$A, 0)), 2968.1) -> 2968.1 | O40: 2937.4 | P40: 2592.96 | Q40: 2562.46 | R40: 2535.59 | S40: 2394.19 | T40: =F40*M40 -> 105321.6 | U40: =T40-L40 -> 3282.12 | V40: =IF(L40>0, U40/L40, 0) -> 0.032165197 | W40: 1.4049885 | X40: 20 | Z40: No | AA40: 2937.4
...

Sheet Core_Watchlist
A1: Month | B1: Company | C1: Company Name | D1: Sector | E1: Theme | F1: Market Cap (MC) | G1: Trend Status | L1: No of shares | P1: 3000000
A2: 46143 | B2: CARYSIL | C2: #VALUE! | D2: {=_FV(C2,"Industry")} -> Homebuilding & Construction Supplies | E2: Consumption | F2: SC (Small Cap) | G2: Strong Trend- Green | I2: {=_FV(C2,"Price")} -> 1138 | J2: =$O$4/31 -> 29032.258 | K2: =J2/I2 -> 25.51165 | L2: 27.492669 | P2: 100000 | Q2: =$P$2/I2 -> 87.873462
A3: 46143 | B3: HBLENGINE | C3: #VALUE! | D3: {=_FV(C3,"Industry")} -> Machinery, Equipment & Components | E3: Industrial | F3: SC (Small Cap) | G3: Strong Trend- Green | I3: {=_FV(C3,"Price")} -> 786.25 | J3: =$O$4/31 -> 29032.258 | K3: =J3/I3 -> 36.924971 | L3: 36.374438 | M3: 7000000 | N3: 1600000 | Q3: =$P$2/I3 -> 127.18601
A4: 46143 | B4: NEULANDLAB | C4: #VALUE! | D4: {=_FV(C4,"Industry")} -> Pharmaceuticals | E4: Health / Pharma / Chem | F4: SC (Small Cap) | G4: Strong Trend- Green | I4: {=_FV(C4,"Price")} -> 16992 | J4: =$O$4/31 -> 29032.258 | K4: =J4/I4 -> 1.7085839 | L4: 1.6881183 | M4: =M3-N3 -> 5400000 | N4: 6 | O4: =M4/N4 -> 900000 | Q4: =$P$2/I4 -> 5.8851224
A5: 46143 | B5: POWERINDIA | C5: #VALUE! | D5: {=_FV(C5,"Industry")} -> Machinery, Equipment & Components | E5: Industrial | F5: MC (Mid Cap) | G5: Strong Trend- Green | I5: {=_FV(C5,"Price")} -> 35190 | J5: =$O$4/31 -> 29032.258 | K5: =J5/I5 -> 0.82501444 | L5: 0.79802798 | Q5: =$P$2/I5 -> 2.8417164
A6: 46143 | B6: SYRMA | C6: #VALUE! | D6: {=_FV(C6,"Industry")} -> Electronic Equipment & Parts | E6: Industrial | F6: SC (Small Cap) | G6: Strong Trend- Green | I6: {=_FV(C6,"Price")} -> 1195.3 | J6: =$O$4/31 -> 29032.258 | K6: =J6/I6 -> 24.288679 | L6: 26.218963 | Q6: =$P$2/I6 -> 83.661006
A7: 46143 | B7: VBL | C7: #VALUE! | D7: {=_FV(C7,"Industry")} -> Beverages | E7: Consumption | F7: LC (Large Cap) | G7: Strong Trend- Green | I7: {=_FV(C7,"Price")} -> 533.4 | J7: =$O$4/31 -> 29032.258 | K7: =J7/I7 -> 54.42868 | L7: 55.246923 | Q7: =$P$2/I7 -> 187.47657
A8: 46143 | B8: BAJAJ-AUTO | C8: #VALUE! | D8: {=_FV(C8,"Industry")} -> Automobiles & Auto Parts | E8: Consumption | F8: LC (Large Cap) | G8: Strong Trend- Green | I8: {=_FV(C8,"Price")} -> 10259 | J8: =$O$4/31 -> 29032.258 | K8: =J8/I8 -> 2.8299306 | L8: 2.7980202 | Q8: =$P$2/I8 -> 9.7475387
A9: 46143 | B9: TIPSMUSIC | C9: #VALUE! | D9: {=_FV(C9,"Industry")} -> Media & Publishing | E9: Technology | F9: SC (Small Cap) | G9: Strong Trend- Green | I9: {=_FV(C9,"Price")} -> 659.85 | J9: =$O$4/31 -> 29032.258 | K9: =J9/I9 -> 43.998269 | L9: 44.310528 | Q9: =$P$2/I9 -> 151.54959
A10: 46143 | B10: AIAENG | C10: #VALUE! | D10: {=_FV(C10,"Industry")} -> Machinery, Equipment & Components | E10: Industrial | F10: SC (Small Cap) | G10: Strong Trend- Green | I10: {=_FV(C10,"Price")} -> 4521.3 | J10: =$O$4/31 -> 29032.258 | K10: =J10/I10 -> 6.4212191 | L10: 6.4192314 | Q10: =$P$2/I10 -> 22.117533
A11: 46143 | B11: ACUTAAS | C11: #VALUE! | D11: {=_FV(C11,"Industry")} -> Chemicals | E11: Health / Pharma / Chem | F11: SC (Small Cap) | G11: Strong Trend- Green | I11: {=_FV(C11,"Price")} -> 3135.7 | J11: =$O$4/31 -> 29032.258 | K11: =J11/I11 -> 9.2586211 | L11: 9.6168333 | Q11: =$P$2/I11 -> 31.890806
A12: 46143 | B12: OFSS | C12: #VALUE! | D12: {=_FV(C12,"Industry")} -> Software & IT Services | E12: Technology | F12: MC (Mid Cap) | G12: Strong Trend- Green | I12: {=_FV(C12,"Price")} -> 9997.5 | J12: =$O$4/31 -> 29032.258 | K12: =J12/I12 -> 2.9039518 | L12: 2.8488135 | Q12: =$P$2/I12 -> 10.002501
